{"name": "test_chat_gateway[case1]", "status": "broken", "statusDetails": {"message": "requests.exceptions.ConnectionError: HTTPConnectionPool(host='localhost', port=8688): Max retries exceeded with url: /api/chatGatWay-internal (Caused by NewConnectionError('<urllib3.connection.HTTPConnection object at 0x000001EAEE2F56A0>: Failed to establish a new connection: [WinError 10061] 由于目标计算机积极拒绝，无法连接。'))", "trace": ".venv\\lib\\site-packages\\urllib3\\connection.py:199: in _new_conn\n    sock = connection.create_connection(\n.venv\\lib\\site-packages\\urllib3\\util\\connection.py:85: in create_connection\n    raise err\n.venv\\lib\\site-packages\\urllib3\\util\\connection.py:73: in create_connection\n    sock.connect(sa)\nE   ConnectionRefusedError: [WinError 10061] 由于目标计算机积极拒绝，无法连接。\n\nThe above exception was the direct cause of the following exception:\n.venv\\lib\\site-packages\\urllib3\\connectionpool.py:789: in urlopen\n    response = self._make_request(\n.venv\\lib\\site-packages\\urllib3\\connectionpool.py:495: in _make_request\n    conn.request(\n.venv\\lib\\site-packages\\urllib3\\connection.py:441: in request\n    self.endheaders()\n..\\AppData\\Local\\Programs\\Python\\Python38\\lib\\http\\client.py:1247: in endheaders\n    self._send_output(message_body, encode_chunked=encode_chunked)\n..\\AppData\\Local\\Programs\\Python\\Python38\\lib\\http\\client.py:1007: in _send_output\n    self.send(msg)\n..\\AppData\\Local\\Programs\\Python\\Python38\\lib\\http\\client.py:947: in send\n    self.connect()\n.venv\\lib\\site-packages\\urllib3\\connection.py:279: in connect\n    self.sock = self._new_conn()\n.venv\\lib\\site-packages\\urllib3\\connection.py:214: in _new_conn\n    raise NewConnectionError(\nE   urllib3.exceptions.NewConnectionError: <urllib3.connection.HTTPConnection object at 0x000001EAEE2F56A0>: Failed to establish a new connection: [WinError 10061] 由于目标计算机积极拒绝，无法连接。\n\nThe above exception was the direct cause of the following exception:\n.venv\\lib\\site-packages\\requests\\adapters.py:667: in send\n    resp = conn.urlopen(\n.venv\\lib\\site-packages\\urllib3\\connectionpool.py:843: in urlopen\n    retries = retries.increment(\n.venv\\lib\\site-packages\\urllib3\\util\\retry.py:519: in increment\n    raise MaxRetryError(_pool, url, reason) from reason  # type: ignore[arg-type]\nE   urllib3.exceptions.MaxRetryError: HTTPConnectionPool(host='localhost', port=8688): Max retries exceeded with url: /api/chatGatWay-internal (Caused by NewConnectionError('<urllib3.connection.HTTPConnection object at 0x000001EAEE2F56A0>: Failed to establish a new connection: [WinError 10061] 由于目标计算机积极拒绝，无法连接。'))\n\nDuring handling of the above exception, another exception occurred:\ntestcase\\test_chat_gateway.py:42: in test_chat_gateway\n    resp = http_request_with_allure(\nutils\\allure_utils.py:288: in http_request_with_allure\n    response = http_utils.request(method, url, **kwargs)\nutils\\http_utils.py:286: in request\n    response = self._make_request(method, url, **kwargs)\nutils\\http_utils.py:129: in _make_request\n    response = self.session.request(\n.venv\\lib\\site-packages\\requests\\sessions.py:589: in request\n    resp = self.send(prep, **send_kwargs)\n.venv\\lib\\site-packages\\requests\\sessions.py:703: in send\n    r = adapter.send(request, **kwargs)\n.venv\\lib\\site-packages\\requests\\adapters.py:700: in send\n    raise ConnectionError(e, request=request)\nE   requests.exceptions.ConnectionError: HTTPConnectionPool(host='localhost', port=8688): Max retries exceeded with url: /api/chatGatWay-internal (Caused by NewConnectionError('<urllib3.connection.HTTPConnection object at 0x000001EAEE2F56A0>: Failed to establish a new connection: [WinError 10061] 由于目标计算机积极拒绝，无法连接。'))"}, "description": "聊天网关测试用例", "steps": [{"name": "测试设置: Unknown.test_chat_gateway[case1]", "status": "passed", "start": 1754271255995, "stop": 1754271255996}, {"name": "执行用例: 2 - 异常请求-缺少message参数", "status": "broken", "statusDetails": {"message": "requests.exceptions.ConnectionError: HTTPConnectionPool(host='localhost', port=8688): Max retries exceeded with url: /api/chatGatWay-internal (Caused by NewConnectionError('<urllib3.connection.HTTPConnection object at 0x000001EAEE2F56A0>: Failed to establish a new connection: [WinError 10061] 由于目标计算机积极拒绝，无法连接。'))\n", "trace": "  File \"C:\\Users\\sy_li\\bgtest\\testcase\\test_chat_gateway.py\", line 42, in test_chat_gateway\n    resp = http_request_with_allure(\n  File \"C:\\Users\\sy_li\\bgtest\\utils\\allure_utils.py\", line 288, in http_request_with_allure\n    response = http_utils.request(method, url, **kwargs)\n  File \"C:\\Users\\sy_li\\bgtest\\utils\\http_utils.py\", line 286, in request\n    response = self._make_request(method, url, **kwargs)\n  File \"C:\\Users\\sy_li\\bgtest\\utils\\http_utils.py\", line 129, in _make_request\n    response = self.session.request(\n  File \"C:\\Users\\sy_li\\bgtest\\.venv\\lib\\site-packages\\requests\\sessions.py\", line 589, in request\n    resp = self.send(prep, **send_kwargs)\n  File \"C:\\Users\\sy_li\\bgtest\\.venv\\lib\\site-packages\\requests\\sessions.py\", line 703, in send\n    r = adapter.send(request, **kwargs)\n  File \"C:\\Users\\sy_li\\bgtest\\.venv\\lib\\site-packages\\requests\\adapters.py\", line 700, in send\n    raise ConnectionError(e, request=request)\n"}, "steps": [{"name": "准备请求参数", "status": "passed", "attachments": [{"name": "请求参数", "source": "1465b1f5-7b17-44dd-ae49-3cf3ed8b282b-attachment.json", "type": "application/json"}], "start": 1754271255997, "stop": 1754271255998}, {"name": "发送HTTP请求", "status": "broken", "statusDetails": {"message": "requests.exceptions.ConnectionError: HTTPConnectionPool(host='localhost', port=8688): Max retries exceeded with url: /api/chatGatWay-internal (Caused by NewConnectionError('<urllib3.connection.HTTPConnection object at 0x000001EAEE2F56A0>: Failed to establish a new connection: [WinError 10061] 由于目标计算机积极拒绝，无法连接。'))\n", "trace": "  File \"C:\\Users\\sy_li\\bgtest\\testcase\\test_chat_gateway.py\", line 42, in test_chat_gateway\n    resp = http_request_with_allure(\n  File \"C:\\Users\\sy_li\\bgtest\\utils\\allure_utils.py\", line 288, in http_request_with_allure\n    response = http_utils.request(method, url, **kwargs)\n  File \"C:\\Users\\sy_li\\bgtest\\utils\\http_utils.py\", line 286, in request\n    response = self._make_request(method, url, **kwargs)\n  File \"C:\\Users\\sy_li\\bgtest\\utils\\http_utils.py\", line 129, in _make_request\n    response = self.session.request(\n  File \"C:\\Users\\sy_li\\bgtest\\.venv\\lib\\site-packages\\requests\\sessions.py\", line 589, in request\n    resp = self.send(prep, **send_kwargs)\n  File \"C:\\Users\\sy_li\\bgtest\\.venv\\lib\\site-packages\\requests\\sessions.py\", line 703, in send\n    r = adapter.send(request, **kwargs)\n  File \"C:\\Users\\sy_li\\bgtest\\.venv\\lib\\site-packages\\requests\\adapters.py\", line 700, in send\n    raise ConnectionError(e, request=request)\n"}, "steps": [{"name": "HTTP请求: POST http://localhost:8688/api/chatGatWay-internal", "status": "broken", "statusDetails": {"message": "requests.exceptions.ConnectionError: HTTPConnectionPool(host='localhost', port=8688): Max retries exceeded with url: /api/chatGatWay-internal (Caused by NewConnectionError('<urllib3.connection.HTTPConnection object at 0x000001EAEE2F56A0>: Failed to establish a new connection: [WinError 10061] 由于目标计算机积极拒绝，无法连接。'))\n", "trace": "  File \"C:\\Users\\sy_li\\bgtest\\utils\\allure_utils.py\", line 288, in http_request_with_allure\n    response = http_utils.request(method, url, **kwargs)\n  File \"C:\\Users\\sy_li\\bgtest\\utils\\http_utils.py\", line 286, in request\n    response = self._make_request(method, url, **kwargs)\n  File \"C:\\Users\\sy_li\\bgtest\\utils\\http_utils.py\", line 129, in _make_request\n    response = self.session.request(\n  File \"C:\\Users\\sy_li\\bgtest\\.venv\\lib\\site-packages\\requests\\sessions.py\", line 589, in request\n    resp = self.send(prep, **send_kwargs)\n  File \"C:\\Users\\sy_li\\bgtest\\.venv\\lib\\site-packages\\requests\\sessions.py\", line 703, in send\n    r = adapter.send(request, **kwargs)\n  File \"C:\\Users\\sy_li\\bgtest\\.venv\\lib\\site-packages\\requests\\adapters.py\", line 700, in send\n    raise ConnectionError(e, request=request)\n"}, "attachments": [{"name": "Request Details", "source": "b07a7f62-5883-4a9c-a570-25e9b11c60c6-attachment.json", "type": "application/json"}, {"name": "HTTP请求异常: POST http://localhost:8688/api/chatGatWay-internal", "source": "a58e0c3d-e55d-4adb-a456-db861475ec72-attachment.json", "type": "application/json"}], "start": 1754271255998, "stop": 1754271260029}], "attachments": [{"name": "错误信息", "source": "2f3337ab-2862-48da-b753-65920c4e0c23-attachment.txt", "type": "text/plain"}], "start": 1754271255998, "stop": 1754271260032}], "attachments": [{"name": "测试用例: 2", "source": "36ad1828-fcb1-4814-8c6a-648f206bc426-attachment.json", "type": "application/json"}], "start": 1754271255996, "stop": 1754271260034}, {"name": "测试清理: Unknown.test_chat_gateway[case1]", "status": "passed", "start": 1754271260227, "stop": 1754271260229}], "attachments": [{"name": "测试异常", "source": "2e71cb65-60a6-48d0-8fc8-e2176e109746-attachment.json", "type": "application/json"}, {"name": "异常堆栈", "source": "9d1b8064-4fad-42da-a6c1-e84368619409-attachment.txt", "type": "text/plain"}, {"name": "log", "source": "92c5d35a-3cf2-4f57-a693-f276c2e6796f-attachment.txt", "type": "text/plain"}], "parameters": [{"name": "case", "value": "{'case_id': 2, 'description': '异常请求-缺少message参数', 'url': 'http://localhost:8688/api/chatGatWay-internal', 'method': 'POST', 'params': {'user_id': 'user002'}, 'expected_result': {'code': 400, 'msg': '参数缺失: message', 'data': {}}}"}], "start": 1754271255996, "stop": 1754271260036, "uuid": "8023cd07-97a4-4570-b4e6-79d5b1f08018", "historyId": "f6f57a812db2780b726abc2497d09cfd", "testCaseId": "1978e2cdf027d526c50a4af93e30c525", "fullName": "testcase.test_chat_gateway#test_chat_gateway", "labels": [{"name": "story", "value": "API测试"}, {"name": "feature", "value": "聊天网关"}, {"name": "parentSuite", "value": "testcase"}, {"name": "suite", "value": "test_chat_gateway"}, {"name": "host", "value": "lihaojie"}, {"name": "thread", "value": "89128-MainThread"}, {"name": "framework", "value": "pytest"}, {"name": "language", "value": "cpython3"}, {"name": "package", "value": "testcase.test_chat_gateway"}], "titlePath": ["testcase", "test_chat_gateway.py"]}