INFO     project_logger:log.py:46 开始测试: Unknown.test_chat_gateway_optimized[case0]
INFO     project_logger:log.py:46 开始执行测试: test_chat_gateway_optimized
INFO     project_logger:log.py:46 请求地址: http://localhost:8688/api/chatGatWay-internal
INFO     project_logger:log.py:46 请求参数: {'message': '你好，今天天气怎么样？', 'user_id': 'user001'}
INFO     api_monitor_logger:log.py:57 HTTP请求开始: {"timestamp": 1754271264.505659, "method": "POST", "url": "http://localhost:8688/api/chatGatWay-internal", "params": {}, "json_data": {"message": "你好，今天天气怎么样？", "user_id": "user001"}, "headers": {}}
ERROR    utils.http_utils:http_utils.py:147 请求失败: HTTPConnectionPool(host='localhost', port=8688): Max retries exceeded with url: /api/chatGatWay-internal (Caused by NewConnectionError('<urllib3.connection.HTTPConnection object at 0x000001EAEDC072B0>: Failed to establish a new connection: [WinError 10061] 由于目标计算机积极拒绝，无法连接。'))
ERROR    api_monitor_logger:log.py:61 HTTP请求失败: {"timestamp": 1754271268.5228996, "method": "POST", "url": "http://localhost:8688/api/chatGatWay-internal", "status_code": null, "execution_time_ms": 4017.24, "response_size": 0, "status": "error", "error": "HTTPConnectionPool(host='localhost', port=8688): Max retries exceeded with url: /api/chatGatWay-internal (Caused by NewConnectionError('<urllib3.connection.HTTPConnection object at 0x000001EAEDC072B0>: Failed to establish a new connection: [WinError 10061] 由于目标计算机积极拒绝，无法连接。'))"}
ERROR    project_logger:log.py:49 测试执行失败: test_chat_gateway_optimized, 耗时: 4.03秒, 错误: 请求失败: HTTPConnectionPool(host='localhost', port=8688): Max retries exceeded with url: /api/chatGatWay-internal (Caused by NewConnectionError('<urllib3.connection.HTTPConnection object at 0x000001EAEDC072B0>: Failed to establish a new connection: [WinError 10061] 由于目标计算机积极拒绝，无法连接。'))
INFO     project_logger:log.py:46 测试完成: Unknown.test_chat_gateway_optimized[case0], 耗时: 4.33秒