{"name": "test_chat_gateway[case2]", "status": "broken", "statusDetails": {"message": "requests.exceptions.ConnectionError: HTTPConnectionPool(host='localhost', port=8688): Max retries exceeded with url: /api/chatGatWay-internal (Caused by NewConnectionError('<urllib3.connection.HTTPConnection object at 0x000001EAEDF7B190>: Failed to establish a new connection: [WinError 10061] 由于目标计算机积极拒绝，无法连接。'))", "trace": ".venv\\lib\\site-packages\\urllib3\\connection.py:199: in _new_conn\n    sock = connection.create_connection(\n.venv\\lib\\site-packages\\urllib3\\util\\connection.py:85: in create_connection\n    raise err\n.venv\\lib\\site-packages\\urllib3\\util\\connection.py:73: in create_connection\n    sock.connect(sa)\nE   ConnectionRefusedError: [WinError 10061] 由于目标计算机积极拒绝，无法连接。\n\nThe above exception was the direct cause of the following exception:\n.venv\\lib\\site-packages\\urllib3\\connectionpool.py:789: in urlopen\n    response = self._make_request(\n.venv\\lib\\site-packages\\urllib3\\connectionpool.py:495: in _make_request\n    conn.request(\n.venv\\lib\\site-packages\\urllib3\\connection.py:441: in request\n    self.endheaders()\n..\\AppData\\Local\\Programs\\Python\\Python38\\lib\\http\\client.py:1247: in endheaders\n    self._send_output(message_body, encode_chunked=encode_chunked)\n..\\AppData\\Local\\Programs\\Python\\Python38\\lib\\http\\client.py:1007: in _send_output\n    self.send(msg)\n..\\AppData\\Local\\Programs\\Python\\Python38\\lib\\http\\client.py:947: in send\n    self.connect()\n.venv\\lib\\site-packages\\urllib3\\connection.py:279: in connect\n    self.sock = self._new_conn()\n.venv\\lib\\site-packages\\urllib3\\connection.py:214: in _new_conn\n    raise NewConnectionError(\nE   urllib3.exceptions.NewConnectionError: <urllib3.connection.HTTPConnection object at 0x000001EAEDF7B190>: Failed to establish a new connection: [WinError 10061] 由于目标计算机积极拒绝，无法连接。\n\nThe above exception was the direct cause of the following exception:\n.venv\\lib\\site-packages\\requests\\adapters.py:667: in send\n    resp = conn.urlopen(\n.venv\\lib\\site-packages\\urllib3\\connectionpool.py:843: in urlopen\n    retries = retries.increment(\n.venv\\lib\\site-packages\\urllib3\\util\\retry.py:519: in increment\n    raise MaxRetryError(_pool, url, reason) from reason  # type: ignore[arg-type]\nE   urllib3.exceptions.MaxRetryError: HTTPConnectionPool(host='localhost', port=8688): Max retries exceeded with url: /api/chatGatWay-internal (Caused by NewConnectionError('<urllib3.connection.HTTPConnection object at 0x000001EAEDF7B190>: Failed to establish a new connection: [WinError 10061] 由于目标计算机积极拒绝，无法连接。'))\n\nDuring handling of the above exception, another exception occurred:\ntestcase\\test_chat_gateway.py:42: in test_chat_gateway\n    resp = http_request_with_allure(\nutils\\allure_utils.py:288: in http_request_with_allure\n    response = http_utils.request(method, url, **kwargs)\nutils\\http_utils.py:286: in request\n    response = self._make_request(method, url, **kwargs)\nutils\\http_utils.py:129: in _make_request\n    response = self.session.request(\n.venv\\lib\\site-packages\\requests\\sessions.py:589: in request\n    resp = self.send(prep, **send_kwargs)\n.venv\\lib\\site-packages\\requests\\sessions.py:703: in send\n    r = adapter.send(request, **kwargs)\n.venv\\lib\\site-packages\\requests\\adapters.py:700: in send\n    raise ConnectionError(e, request=request)\nE   requests.exceptions.ConnectionError: HTTPConnectionPool(host='localhost', port=8688): Max retries exceeded with url: /api/chatGatWay-internal (Caused by NewConnectionError('<urllib3.connection.HTTPConnection object at 0x000001EAEDF7B190>: Failed to establish a new connection: [WinError 10061] 由于目标计算机积极拒绝，无法连接。'))"}, "description": "聊天网关测试用例", "steps": [{"name": "测试设置: Unknown.test_chat_gateway[case2]", "status": "passed", "start": 1754271260234, "stop": 1754271260235}, {"name": "执行用例: 3 - 正常请求-英文问题", "status": "broken", "statusDetails": {"message": "requests.exceptions.ConnectionError: HTTPConnectionPool(host='localhost', port=8688): Max retries exceeded with url: /api/chatGatWay-internal (Caused by NewConnectionError('<urllib3.connection.HTTPConnection object at 0x000001EAEDF7B190>: Failed to establish a new connection: [WinError 10061] 由于目标计算机积极拒绝，无法连接。'))\n", "trace": "  File \"C:\\Users\\sy_li\\bgtest\\testcase\\test_chat_gateway.py\", line 42, in test_chat_gateway\n    resp = http_request_with_allure(\n  File \"C:\\Users\\sy_li\\bgtest\\utils\\allure_utils.py\", line 288, in http_request_with_allure\n    response = http_utils.request(method, url, **kwargs)\n  File \"C:\\Users\\sy_li\\bgtest\\utils\\http_utils.py\", line 286, in request\n    response = self._make_request(method, url, **kwargs)\n  File \"C:\\Users\\sy_li\\bgtest\\utils\\http_utils.py\", line 129, in _make_request\n    response = self.session.request(\n  File \"C:\\Users\\sy_li\\bgtest\\.venv\\lib\\site-packages\\requests\\sessions.py\", line 589, in request\n    resp = self.send(prep, **send_kwargs)\n  File \"C:\\Users\\sy_li\\bgtest\\.venv\\lib\\site-packages\\requests\\sessions.py\", line 703, in send\n    r = adapter.send(request, **kwargs)\n  File \"C:\\Users\\sy_li\\bgtest\\.venv\\lib\\site-packages\\requests\\adapters.py\", line 700, in send\n    raise ConnectionError(e, request=request)\n"}, "steps": [{"name": "准备请求参数", "status": "passed", "attachments": [{"name": "请求参数", "source": "bf4709cb-53c8-4f5d-838b-f46f8c24b124-attachment.json", "type": "application/json"}], "start": 1754271260236, "stop": 1754271260237}, {"name": "发送HTTP请求", "status": "broken", "statusDetails": {"message": "requests.exceptions.ConnectionError: HTTPConnectionPool(host='localhost', port=8688): Max retries exceeded with url: /api/chatGatWay-internal (Caused by NewConnectionError('<urllib3.connection.HTTPConnection object at 0x000001EAEDF7B190>: Failed to establish a new connection: [WinError 10061] 由于目标计算机积极拒绝，无法连接。'))\n", "trace": "  File \"C:\\Users\\sy_li\\bgtest\\testcase\\test_chat_gateway.py\", line 42, in test_chat_gateway\n    resp = http_request_with_allure(\n  File \"C:\\Users\\sy_li\\bgtest\\utils\\allure_utils.py\", line 288, in http_request_with_allure\n    response = http_utils.request(method, url, **kwargs)\n  File \"C:\\Users\\sy_li\\bgtest\\utils\\http_utils.py\", line 286, in request\n    response = self._make_request(method, url, **kwargs)\n  File \"C:\\Users\\sy_li\\bgtest\\utils\\http_utils.py\", line 129, in _make_request\n    response = self.session.request(\n  File \"C:\\Users\\sy_li\\bgtest\\.venv\\lib\\site-packages\\requests\\sessions.py\", line 589, in request\n    resp = self.send(prep, **send_kwargs)\n  File \"C:\\Users\\sy_li\\bgtest\\.venv\\lib\\site-packages\\requests\\sessions.py\", line 703, in send\n    r = adapter.send(request, **kwargs)\n  File \"C:\\Users\\sy_li\\bgtest\\.venv\\lib\\site-packages\\requests\\adapters.py\", line 700, in send\n    raise ConnectionError(e, request=request)\n"}, "steps": [{"name": "HTTP请求: POST http://localhost:8688/api/chatGatWay-internal", "status": "broken", "statusDetails": {"message": "requests.exceptions.ConnectionError: HTTPConnectionPool(host='localhost', port=8688): Max retries exceeded with url: /api/chatGatWay-internal (Caused by NewConnectionError('<urllib3.connection.HTTPConnection object at 0x000001EAEDF7B190>: Failed to establish a new connection: [WinError 10061] 由于目标计算机积极拒绝，无法连接。'))\n", "trace": "  File \"C:\\Users\\sy_li\\bgtest\\utils\\allure_utils.py\", line 288, in http_request_with_allure\n    response = http_utils.request(method, url, **kwargs)\n  File \"C:\\Users\\sy_li\\bgtest\\utils\\http_utils.py\", line 286, in request\n    response = self._make_request(method, url, **kwargs)\n  File \"C:\\Users\\sy_li\\bgtest\\utils\\http_utils.py\", line 129, in _make_request\n    response = self.session.request(\n  File \"C:\\Users\\sy_li\\bgtest\\.venv\\lib\\site-packages\\requests\\sessions.py\", line 589, in request\n    resp = self.send(prep, **send_kwargs)\n  File \"C:\\Users\\sy_li\\bgtest\\.venv\\lib\\site-packages\\requests\\sessions.py\", line 703, in send\n    r = adapter.send(request, **kwargs)\n  File \"C:\\Users\\sy_li\\bgtest\\.venv\\lib\\site-packages\\requests\\adapters.py\", line 700, in send\n    raise ConnectionError(e, request=request)\n"}, "attachments": [{"name": "Request Details", "source": "421c1195-dfa7-49ac-8162-c9c87fa26c4a-attachment.json", "type": "application/json"}, {"name": "HTTP请求异常: POST http://localhost:8688/api/chatGatWay-internal", "source": "b6825b6b-7d75-4602-8315-26fde5d849a5-attachment.json", "type": "application/json"}], "start": 1754271260237, "stop": 1754271264249}], "attachments": [{"name": "错误信息", "source": "bb9c569e-04c8-4f5b-9968-79e73ee7ea01-attachment.txt", "type": "text/plain"}], "start": 1754271260237, "stop": 1754271264250}], "attachments": [{"name": "测试用例: 3", "source": "0372e0e2-ef61-4c2d-b394-c12514546b99-attachment.json", "type": "application/json"}], "start": 1754271260236, "stop": 1754271264251}, {"name": "测试清理: Unknown.test_chat_gateway[case2]", "status": "passed", "start": 1754271264495, "stop": 1754271264497}], "attachments": [{"name": "测试异常", "source": "2b79c7e2-4f01-4363-94c7-7e992137959b-attachment.json", "type": "application/json"}, {"name": "异常堆栈", "source": "a8377081-792d-4eeb-960d-a6b0333d607b-attachment.txt", "type": "text/plain"}, {"name": "log", "source": "e0a4e72f-3865-422f-9b29-3bf91376099f-attachment.txt", "type": "text/plain"}], "parameters": [{"name": "case", "value": "{'case_id': 3, 'description': '正常请求-英文问题', 'url': 'http://localhost:8688/api/chatGatWay-internal', 'method': 'POST', 'params': {'message': 'What is the capital of France?', 'user_id': 'user003'}, 'expected_result': {'code': 0, 'msg': 'success', 'data': {'reply': 'The capital of France is Paris.'}}}"}], "start": 1754271260236, "stop": 1754271264251, "uuid": "8c89d190-cd55-419a-bad2-a09f03fdcaff", "historyId": "25e7db82dff32a50e67dd75fd1961c11", "testCaseId": "1978e2cdf027d526c50a4af93e30c525", "fullName": "testcase.test_chat_gateway#test_chat_gateway", "labels": [{"name": "story", "value": "API测试"}, {"name": "feature", "value": "聊天网关"}, {"name": "parentSuite", "value": "testcase"}, {"name": "suite", "value": "test_chat_gateway"}, {"name": "host", "value": "lihaojie"}, {"name": "thread", "value": "89128-MainThread"}, {"name": "framework", "value": "pytest"}, {"name": "language", "value": "cpython3"}, {"name": "package", "value": "testcase.test_chat_gateway"}], "titlePath": ["testcase", "test_chat_gateway.py"]}