INFO     project_logger:log.py:46 开始测试: Unknown.test_chat_gateway_file
INFO     project_logger:log.py:46 聊天网关测试 - 用例: 1 - 正常请求-简单问题
INFO     api_monitor_logger:log.py:57 HTTP请求开始: {"timestamp": 1754201200.484309, "method": "POST", "url": "http://localhost:8688/api/chatGatWay-internal", "params": {}, "json_data": {"message": "你好，今天天气怎么样？", "user_id": "user001"}, "headers": {}}
ERROR    utils.http_utils:http_utils.py:147 请求失败: HTTPConnectionPool(host='localhost', port=8688): Max retries exceeded with url: /api/chatGatWay-internal (Caused by NewConnectionError('<urllib3.connection.HTTPConnection object at 0x0000012610A178A0>: Failed to establish a new connection: [WinError 10061] 由于目标计算机积极拒绝，无法连接。'))
ERROR    api_monitor_logger:log.py:61 HTTP请求失败: {"timestamp": 1754201204.5597785, "method": "POST", "url": "http://localhost:8688/api/chatGatWay-internal", "status_code": null, "execution_time_ms": 4075.47, "response_size": 0, "status": "error", "error": "HTTPConnectionPool(host='localhost', port=8688): Max retries exceeded with url: /api/chatGatWay-internal (Caused by NewConnectionError('<urllib3.connection.HTTPConnection object at 0x0000012610A178A0>: Failed to establish a new connection: [WinError 10061] 由于目标计算机积极拒绝，无法连接。'))"}
ERROR    project_logger:log.py:49 聊天网关测试执行失败: HTTPConnectionPool(host='localhost', port=8688): Max retries exceeded with url: /api/chatGatWay-internal (Caused by NewConnectionError('<urllib3.connection.HTTPConnection object at 0x0000012610A178A0>: Failed to establish a new connection: [WinError 10061] 由于目标计算机积极拒绝，无法连接。'))
INFO     project_logger:log.py:46 测试完成: Unknown.test_chat_gateway_file, 耗时: 4.09秒