{"name": "test_chat_gateway_optimized[case1]", "status": "broken", "statusDetails": {"message": "Exception: 请求失败: HTTPConnectionPool(host='localhost', port=8688): Max retries exceeded with url: /api/chatGatWay-internal (Caused by NewConnectionError('<urllib3.connection.HTTPConnection object at 0x0000012610A623F0>: Failed to establish a new connection: [WinError 10061] 由于目标计算机积极拒绝，无法连接。'))", "trace": "C:\\Python313\\Lib\\site-packages\\urllib3\\connection.py:198: in _new_conn\n    sock = connection.create_connection(\nC:\\Python313\\Lib\\site-packages\\urllib3\\util\\connection.py:85: in create_connection\n    raise err\nC:\\Python313\\Lib\\site-packages\\urllib3\\util\\connection.py:73: in create_connection\n    sock.connect(sa)\nE   ConnectionRefusedError: [WinError 10061] 由于目标计算机积极拒绝，无法连接。\n\nThe above exception was the direct cause of the following exception:\nC:\\Python313\\Lib\\site-packages\\urllib3\\connectionpool.py:787: in urlopen\n    response = self._make_request(\nC:\\Python313\\Lib\\site-packages\\urllib3\\connectionpool.py:493: in _make_request\n    conn.request(\nC:\\Python313\\Lib\\site-packages\\urllib3\\connection.py:494: in request\n    self.endheaders()\nC:\\Python313\\Lib\\http\\client.py:1333: in endheaders\n    self._send_output(message_body, encode_chunked=encode_chunked)\nC:\\Python313\\Lib\\http\\client.py:1093: in _send_output\n    self.send(msg)\nC:\\Python313\\Lib\\http\\client.py:1037: in send\n    self.connect()\nC:\\Python313\\Lib\\site-packages\\urllib3\\connection.py:325: in connect\n    self.sock = self._new_conn()\nC:\\Python313\\Lib\\site-packages\\urllib3\\connection.py:213: in _new_conn\n    raise NewConnectionError(\nE   urllib3.exceptions.NewConnectionError: <urllib3.connection.HTTPConnection object at 0x0000012610A623F0>: Failed to establish a new connection: [WinError 10061] 由于目标计算机积极拒绝，无法连接。\n\nThe above exception was the direct cause of the following exception:\nC:\\Python313\\Lib\\site-packages\\requests\\adapters.py:667: in send\n    resp = conn.urlopen(\nC:\\Python313\\Lib\\site-packages\\urllib3\\connectionpool.py:841: in urlopen\n    retries = retries.increment(\nC:\\Python313\\Lib\\site-packages\\urllib3\\util\\retry.py:519: in increment\n    raise MaxRetryError(_pool, url, reason) from reason  # type: ignore[arg-type]\nE   urllib3.exceptions.MaxRetryError: HTTPConnectionPool(host='localhost', port=8688): Max retries exceeded with url: /api/chatGatWay-internal (Caused by NewConnectionError('<urllib3.connection.HTTPConnection object at 0x0000012610A623F0>: Failed to establish a new connection: [WinError 10061] 由于目标计算机积极拒绝，无法连接。'))\n\nDuring handling of the above exception, another exception occurred:\ncommon\\test_utils.py:107: in execute_http_request\n    resp = http_request_with_allure(\nutils\\allure_utils.py:288: in http_request_with_allure\n    response = http_utils.request(method, url, **kwargs)\nutils\\http_utils.py:286: in request\n    response = self._make_request(method, url, **kwargs)\nutils\\http_utils.py:129: in _make_request\n    response = self.session.request(\nC:\\Python313\\Lib\\site-packages\\requests\\sessions.py:589: in request\n    resp = self.send(prep, **send_kwargs)\nC:\\Python313\\Lib\\site-packages\\requests\\sessions.py:703: in send\n    r = adapter.send(request, **kwargs)\nC:\\Python313\\Lib\\site-packages\\requests\\adapters.py:700: in send\n    raise ConnectionError(e, request=request)\nE   requests.exceptions.ConnectionError: HTTPConnectionPool(host='localhost', port=8688): Max retries exceeded with url: /api/chatGatWay-internal (Caused by NewConnectionError('<urllib3.connection.HTTPConnection object at 0x0000012610A623F0>: Failed to establish a new connection: [WinError 10061] 由于目标计算机积极拒绝，无法连接。'))\n\nDuring handling of the above exception, another exception occurred:\ntestcase\\test_chat_gateway_optimized.py:39: in test_chat_gateway_optimized\n    success = test_utils.execute_test_case(case, use_allure=True)\ncommon\\test_utils.py:274: in execute_test_case\n    response = self.execute_http_request(\ncommon\\test_utils.py:133: in execute_http_request\n    raise Exception(error_msg)\nE   Exception: 请求失败: HTTPConnectionPool(host='localhost', port=8688): Max retries exceeded with url: /api/chatGatWay-internal (Caused by NewConnectionError('<urllib3.connection.HTTPConnection object at 0x0000012610A623F0>: Failed to establish a new connection: [WinError 10061] 由于目标计算机积极拒绝，无法连接。'))"}, "description": "优化后的聊天网关测试用例", "steps": [{"name": "测试设置: Unknown.test_chat_gateway_optimized[case1]", "status": "passed", "start": 1754200638543, "stop": 1754200638552}, {"name": "测试用例: 聊天网关API测试", "status": "broken", "statusDetails": {"message": "Exception: 请求失败: HTTPConnectionPool(host='localhost', port=8688): Max retries exceeded with url: /api/chatGatWay-internal (Caused by NewConnectionError('<urllib3.connection.HTTPConnection object at 0x0000012610A623F0>: Failed to establish a new connection: [WinError 10061] 由于目标计算机积极拒绝，无法连接。'))\n", "trace": "  File \"E:\\bgtest\\utils\\allure_decorators.py\", line 31, in wrapper\n    result = func(*args, **kwargs)\n  File \"E:\\bgtest\\utils\\test_decorators.py\", line 29, in wrapper\n    return func(*args, **kwargs)\n  File \"E:\\bgtest\\utils\\allure_decorators.py\", line 62, in wrapper\n    result = func(*args, **kwargs)\n  File \"E:\\bgtest\\utils\\test_decorators.py\", line 54, in wrapper\n    return func(*args, **kwargs)\n  File \"E:\\bgtest\\utils\\allure_decorators.py\", line 80, in wrapper\n    result = func(*args, **kwargs)\n  File \"E:\\bgtest\\utils\\test_decorators.py\", line 79, in wrapper\n    return func(*args, **kwargs)\n  File \"E:\\bgtest\\utils\\test_decorators.py\", line 300, in wrapper\n    return func(*args, **kwargs)\n  File \"E:\\bgtest\\utils\\test_decorators.py\", line 210, in wrapper\n    result = func(*args, **kwargs)\n  File \"E:\\bgtest\\testcase\\test_chat_gateway_optimized.py\", line 39, in test_chat_gateway_optimized\n    success = test_utils.execute_test_case(case, use_allure=True)\n  File \"E:\\bgtest\\common\\test_utils.py\", line 274, in execute_test_case\n    response = self.execute_http_request(\n        url=case_data['url'],\n    ...<3 lines>...\n        use_allure=use_allure\n    )\n  File \"E:\\bgtest\\common\\test_utils.py\", line 133, in execute_http_request\n    raise Exception(error_msg)\n"}, "steps": [{"name": "API测试: 聊天网关", "status": "broken", "statusDetails": {"message": "Exception: 请求失败: HTTPConnectionPool(host='localhost', port=8688): Max retries exceeded with url: /api/chatGatWay-internal (Caused by NewConnectionError('<urllib3.connection.HTTPConnection object at 0x0000012610A623F0>: Failed to establish a new connection: [WinError 10061] 由于目标计算机积极拒绝，无法连接。'))\n", "trace": "  File \"E:\\bgtest\\utils\\allure_decorators.py\", line 62, in wrapper\n    result = func(*args, **kwargs)\n  File \"E:\\bgtest\\utils\\test_decorators.py\", line 54, in wrapper\n    return func(*args, **kwargs)\n  File \"E:\\bgtest\\utils\\allure_decorators.py\", line 80, in wrapper\n    result = func(*args, **kwargs)\n  File \"E:\\bgtest\\utils\\test_decorators.py\", line 79, in wrapper\n    return func(*args, **kwargs)\n  File \"E:\\bgtest\\utils\\test_decorators.py\", line 300, in wrapper\n    return func(*args, **kwargs)\n  File \"E:\\bgtest\\utils\\test_decorators.py\", line 210, in wrapper\n    result = func(*args, **kwargs)\n  File \"E:\\bgtest\\testcase\\test_chat_gateway_optimized.py\", line 39, in test_chat_gateway_optimized\n    success = test_utils.execute_test_case(case, use_allure=True)\n  File \"E:\\bgtest\\common\\test_utils.py\", line 274, in execute_test_case\n    response = self.execute_http_request(\n        url=case_data['url'],\n    ...<3 lines>...\n        use_allure=use_allure\n    )\n  File \"E:\\bgtest\\common\\test_utils.py\", line 133, in execute_http_request\n    raise Exception(error_msg)\n"}, "steps": [{"name": "数据驱动测试: test_chat_gateway.yaml", "status": "broken", "statusDetails": {"message": "Exception: 请求失败: HTTPConnectionPool(host='localhost', port=8688): Max retries exceeded with url: /api/chatGatWay-internal (Caused by NewConnectionError('<urllib3.connection.HTTPConnection object at 0x0000012610A623F0>: Failed to establish a new connection: [WinError 10061] 由于目标计算机积极拒绝，无法连接。'))\n", "trace": "  File \"E:\\bgtest\\utils\\allure_decorators.py\", line 80, in wrapper\n    result = func(*args, **kwargs)\n  File \"E:\\bgtest\\utils\\test_decorators.py\", line 79, in wrapper\n    return func(*args, **kwargs)\n  File \"E:\\bgtest\\utils\\test_decorators.py\", line 300, in wrapper\n    return func(*args, **kwargs)\n  File \"E:\\bgtest\\utils\\test_decorators.py\", line 210, in wrapper\n    result = func(*args, **kwargs)\n  File \"E:\\bgtest\\testcase\\test_chat_gateway_optimized.py\", line 39, in test_chat_gateway_optimized\n    success = test_utils.execute_test_case(case, use_allure=True)\n  File \"E:\\bgtest\\common\\test_utils.py\", line 274, in execute_test_case\n    response = self.execute_http_request(\n        url=case_data['url'],\n    ...<3 lines>...\n        use_allure=use_allure\n    )\n  File \"E:\\bgtest\\common\\test_utils.py\", line 133, in execute_http_request\n    raise Exception(error_msg)\n"}, "steps": [{"name": "执行用例: 2 - 异常请求-缺少message参数", "status": "broken", "statusDetails": {"message": "Exception: 请求失败: HTTPConnectionPool(host='localhost', port=8688): Max retries exceeded with url: /api/chatGatWay-internal (Caused by NewConnectionError('<urllib3.connection.HTTPConnection object at 0x0000012610A623F0>: Failed to establish a new connection: [WinError 10061] 由于目标计算机积极拒绝，无法连接。'))\n", "trace": "  File \"E:\\bgtest\\common\\test_utils.py\", line 274, in execute_test_case\n    response = self.execute_http_request(\n        url=case_data['url'],\n    ...<3 lines>...\n        use_allure=use_allure\n    )\n  File \"E:\\bgtest\\common\\test_utils.py\", line 133, in execute_http_request\n    raise Exception(error_msg)\n"}, "steps": [{"name": "准备请求参数", "status": "passed", "attachments": [{"name": "请求参数", "source": "c6aad045-0f2d-4324-add5-118091984afb-attachment.json", "type": "application/json"}], "start": 1754200638559, "stop": 1754200638562}, {"name": "发送POST请求到 http://localhost:8688/api/chatGatWay-internal", "status": "broken", "statusDetails": {"message": "Exception: 请求失败: HTTPConnectionPool(host='localhost', port=8688): Max retries exceeded with url: /api/chatGatWay-internal (Caused by NewConnectionError('<urllib3.connection.HTTPConnection object at 0x0000012610A623F0>: Failed to establish a new connection: [WinError 10061] 由于目标计算机积极拒绝，无法连接。'))\n", "trace": "  File \"E:\\bgtest\\common\\test_utils.py\", line 133, in execute_http_request\n    raise Exception(error_msg)\n"}, "steps": [{"name": "HTTP请求: POST http://localhost:8688/api/chatGatWay-internal", "status": "broken", "statusDetails": {"message": "requests.exceptions.ConnectionError: HTTPConnectionPool(host='localhost', port=8688): Max retries exceeded with url: /api/chatGatWay-internal (Caused by NewConnectionError('<urllib3.connection.HTTPConnection object at 0x0000012610A623F0>: Failed to establish a new connection: [WinError 10061] 由于目标计算机积极拒绝，无法连接。'))\n", "trace": "  File \"E:\\bgtest\\utils\\allure_utils.py\", line 288, in http_request_with_allure\n    response = http_utils.request(method, url, **kwargs)\n  File \"E:\\bgtest\\utils\\http_utils.py\", line 286, in request\n    response = self._make_request(method, url, **kwargs)\n  File \"E:\\bgtest\\utils\\http_utils.py\", line 129, in _make_request\n    response = self.session.request(\n        method=method,\n    ...<3 lines>...\n        **kwargs\n    )\n  File \"C:\\Python313\\Lib\\site-packages\\requests\\sessions.py\", line 589, in request\n    resp = self.send(prep, **send_kwargs)\n  File \"C:\\Python313\\Lib\\site-packages\\requests\\sessions.py\", line 703, in send\n    r = adapter.send(request, **kwargs)\n  File \"C:\\Python313\\Lib\\site-packages\\requests\\adapters.py\", line 700, in send\n    raise ConnectionError(e, request=request)\n"}, "attachments": [{"name": "Request Details", "source": "8dc44708-2160-4c67-aaad-25a19bc8f01d-attachment.json", "type": "application/json"}, {"name": "HTTP请求异常: POST http://localhost:8688/api/chatGatWay-internal", "source": "4fff4a51-bd79-4448-9d56-0f2c55576066-attachment.json", "type": "application/json"}], "start": 1754200638563, "stop": 1754200642671}], "attachments": [{"name": "错误信息", "source": "ecaee85f-5b0d-407b-abff-20eac300ac76-attachment.txt", "type": "text/plain"}], "start": 1754200638563, "stop": 1754200642678}], "attachments": [{"name": "测试用例: 2", "source": "314d9574-7102-4476-accb-1c08075a4692-attachment.json", "type": "application/json"}], "start": 1754200638558, "stop": 1754200642681}], "attachments": [{"name": "数据驱动信息", "source": "100550dc-0257-4224-bd47-2cf12b27ded9-attachment.txt", "type": "text/plain"}, {"name": "数据驱动测试异常: test_chat_gateway.yaml", "source": "16f054fd-fbdd-4a92-8c26-bc0524e236cb-attachment.json", "type": "application/json"}], "start": 1754200638557, "stop": 1754200642700}], "attachments": [{"name": "API信息", "source": "c4eeaf16-e3e6-431f-8837-ac6998900e7f-attachment.txt", "type": "text/plain"}, {"name": "API测试异常: 聊天网关", "source": "2ec41dad-a2ac-40b5-a15a-854783660bf4-attachment.json", "type": "application/json"}], "start": 1754200638555, "stop": 1754200642716}], "attachments": [{"name": "测试用例异常: 聊天网关API测试", "source": "437e1369-fd6d-4960-8f46-97597a5714f2-attachment.json", "type": "application/json"}], "start": 1754200638555, "stop": 1754200642735}, {"name": "测试清理: Unknown.test_chat_gateway_optimized[case1]", "status": "passed", "start": 1754200643394, "stop": 1754200643401}], "attachments": [{"name": "测试异常", "source": "5d399539-f172-4f3e-bf6c-7818e00cf3d1-attachment.json", "type": "application/json"}, {"name": "异常堆栈", "source": "b85e08af-82ea-4afd-90eb-0fd5c50b5030-attachment.txt", "type": "text/plain"}, {"name": "log", "source": "7468a0be-2edd-4c83-b70e-d697e28918f4-attachment.txt", "type": "text/plain"}], "parameters": [{"name": "case", "value": "{'case_id': 2, 'description': '异常请求-缺少message参数', 'url': 'http://localhost:8688/api/chatGatWay-internal', 'method': 'POST', 'params': {'user_id': 'user002'}, 'expected_result': {'code': 400, 'msg': '参数缺失: message', 'data': {}}}"}], "start": 1754200638555, "stop": 1754200642744, "uuid": "d1cc8f9d-5239-40cd-af83-f8bd63f5c59f", "historyId": "47d4f1acb122ceaa3cba5f27fc09017b", "testCaseId": "2a48a67b57e896f2d1924bc3e0d75f83", "fullName": "testcase.test_chat_gateway_optimized#test_chat_gateway_optimized", "labels": [{"name": "feature", "value": "聊天网关"}, {"name": "story", "value": "API测试"}, {"name": "severity", "value": "critical"}, {"name": "tag", "value": "smoke"}, {"name": "parentSuite", "value": "testcase"}, {"name": "suite", "value": "test_chat_gateway_optimized"}, {"name": "host", "value": "Ly0217"}, {"name": "thread", "value": "231192-MainThread"}, {"name": "framework", "value": "pytest"}, {"name": "language", "value": "cpython3"}, {"name": "package", "value": "testcase.test_chat_gateway_optimized"}], "titlePath": ["testcase", "test_chat_gateway_optimized.py"]}