{"name": "test_chat_gateway[case1]", "status": "broken", "statusDetails": {"message": "requests.exceptions.ConnectionError: HTTPConnectionPool(host='localhost', port=8688): Max retries exceeded with url: /api/chatGatWay-internal (Caused by NewConnectionError('<urllib3.connection.HTTPConnection object at 0x000001A5B6A32E90>: Failed to establish a new connection: [WinError 10061] 由于目标计算机积极拒绝，无法连接。'))", "trace": "C:\\Python313\\Lib\\site-packages\\urllib3\\connection.py:198: in _new_conn\n    sock = connection.create_connection(\nC:\\Python313\\Lib\\site-packages\\urllib3\\util\\connection.py:85: in create_connection\n    raise err\nC:\\Python313\\Lib\\site-packages\\urllib3\\util\\connection.py:73: in create_connection\n    sock.connect(sa)\nE   ConnectionRefusedError: [WinError 10061] 由于目标计算机积极拒绝，无法连接。\n\nThe above exception was the direct cause of the following exception:\nC:\\Python313\\Lib\\site-packages\\urllib3\\connectionpool.py:787: in urlopen\n    response = self._make_request(\nC:\\Python313\\Lib\\site-packages\\urllib3\\connectionpool.py:493: in _make_request\n    conn.request(\nC:\\Python313\\Lib\\site-packages\\urllib3\\connection.py:494: in request\n    self.endheaders()\nC:\\Python313\\Lib\\http\\client.py:1333: in endheaders\n    self._send_output(message_body, encode_chunked=encode_chunked)\nC:\\Python313\\Lib\\http\\client.py:1093: in _send_output\n    self.send(msg)\nC:\\Python313\\Lib\\http\\client.py:1037: in send\n    self.connect()\nC:\\Python313\\Lib\\site-packages\\urllib3\\connection.py:325: in connect\n    self.sock = self._new_conn()\n                ^^^^^^^^^^^^^^^^\nC:\\Python313\\Lib\\site-packages\\urllib3\\connection.py:213: in _new_conn\n    raise NewConnectionError(\nE   urllib3.exceptions.NewConnectionError: <urllib3.connection.HTTPConnection object at 0x000001A5B6A32E90>: Failed to establish a new connection: [WinError 10061] 由于目标计算机积极拒绝，无法连接。\n\nThe above exception was the direct cause of the following exception:\nC:\\Python313\\Lib\\site-packages\\requests\\adapters.py:667: in send\n    resp = conn.urlopen(\nC:\\Python313\\Lib\\site-packages\\urllib3\\connectionpool.py:841: in urlopen\n    retries = retries.increment(\nC:\\Python313\\Lib\\site-packages\\urllib3\\util\\retry.py:519: in increment\n    raise MaxRetryError(_pool, url, reason) from reason  # type: ignore[arg-type]\n    ^^^^^^^^^^^^^^^^^^^^^^^^^^^^^^^^^^^^^^^^^^^^^^^^^^^\nE   urllib3.exceptions.MaxRetryError: HTTPConnectionPool(host='localhost', port=8688): Max retries exceeded with url: /api/chatGatWay-internal (Caused by NewConnectionError('<urllib3.connection.HTTPConnection object at 0x000001A5B6A32E90>: Failed to establish a new connection: [WinError 10061] 由于目标计算机积极拒绝，无法连接。'))\n\nDuring handling of the above exception, another exception occurred:\ntestcase\\test_chat_gateway.py:42: in test_chat_gateway\n    resp = http_request_with_allure(\nutils\\allure_utils.py:282: in http_request_with_allure\n    response = http_utils.request(method, url, **kwargs)\n               ^^^^^^^^^^^^^^^^^^^^^^^^^^^^^^^^^^^^^^^^^\nutils\\http_utils.py:286: in request\n    response = self._make_request(method, url, **kwargs)\n               ^^^^^^^^^^^^^^^^^^^^^^^^^^^^^^^^^^^^^^^^^\nutils\\http_utils.py:129: in _make_request\n    response = self.session.request(\nC:\\Python313\\Lib\\site-packages\\requests\\sessions.py:589: in request\n    resp = self.send(prep, **send_kwargs)\n           ^^^^^^^^^^^^^^^^^^^^^^^^^^^^^^\nC:\\Python313\\Lib\\site-packages\\requests\\sessions.py:703: in send\n    r = adapter.send(request, **kwargs)\n        ^^^^^^^^^^^^^^^^^^^^^^^^^^^^^^^\nC:\\Python313\\Lib\\site-packages\\requests\\adapters.py:700: in send\n    raise ConnectionError(e, request=request)\nE   requests.exceptions.ConnectionError: HTTPConnectionPool(host='localhost', port=8688): Max retries exceeded with url: /api/chatGatWay-internal (Caused by NewConnectionError('<urllib3.connection.HTTPConnection object at 0x000001A5B6A32E90>: Failed to establish a new connection: [WinError 10061] 由于目标计算机积极拒绝，无法连接。'))"}, "description": "聊天网关测试用例", "steps": [{"name": "测试设置: Unknown.test_chat_gateway[case1]", "status": "passed", "start": 1754135083720, "stop": 1754135083722}, {"name": "执行用例: 2 - 异常请求-缺少message参数", "status": "broken", "statusDetails": {"message": "requests.exceptions.ConnectionError: HTTPConnectionPool(host='localhost', port=8688): Max retries exceeded with url: /api/chatGatWay-internal (Caused by NewConnectionError('<urllib3.connection.HTTPConnection object at 0x000001A5B6A32E90>: Failed to establish a new connection: [WinError 10061] 由于目标计算机积极拒绝，无法连接。'))\n", "trace": "  File \"E:\\bgtest\\testcase\\test_chat_gateway.py\", line 42, in test_chat_gateway\n    resp = http_request_with_allure(\n        method=\"POST\",\n        url=url,\n        json_data=params\n    )\n  File \"E:\\bgtest\\utils\\allure_utils.py\", line 282, in http_request_with_allure\n    response = http_utils.request(method, url, **kwargs)\n  File \"E:\\bgtest\\utils\\http_utils.py\", line 286, in request\n    response = self._make_request(method, url, **kwargs)\n  File \"E:\\bgtest\\utils\\http_utils.py\", line 129, in _make_request\n    response = self.session.request(\n        method=method,\n    ...<3 lines>...\n        **kwargs\n    )\n  File \"C:\\Python313\\Lib\\site-packages\\requests\\sessions.py\", line 589, in request\n    resp = self.send(prep, **send_kwargs)\n  File \"C:\\Python313\\Lib\\site-packages\\requests\\sessions.py\", line 703, in send\n    r = adapter.send(request, **kwargs)\n  File \"C:\\Python313\\Lib\\site-packages\\requests\\adapters.py\", line 700, in send\n    raise ConnectionError(e, request=request)\n"}, "steps": [{"name": "准备请求参数", "status": "passed", "attachments": [{"name": "请求参数", "source": "9b195f6c-0c19-446e-978f-5ddb153c255a-attachment.json", "type": "application/json"}], "start": 1754135083726, "stop": 1754135083728}, {"name": "发送HTTP请求", "status": "broken", "statusDetails": {"message": "requests.exceptions.ConnectionError: HTTPConnectionPool(host='localhost', port=8688): Max retries exceeded with url: /api/chatGatWay-internal (Caused by NewConnectionError('<urllib3.connection.HTTPConnection object at 0x000001A5B6A32E90>: Failed to establish a new connection: [WinError 10061] 由于目标计算机积极拒绝，无法连接。'))\n", "trace": "  File \"E:\\bgtest\\testcase\\test_chat_gateway.py\", line 42, in test_chat_gateway\n    resp = http_request_with_allure(\n        method=\"POST\",\n        url=url,\n        json_data=params\n    )\n  File \"E:\\bgtest\\utils\\allure_utils.py\", line 282, in http_request_with_allure\n    response = http_utils.request(method, url, **kwargs)\n  File \"E:\\bgtest\\utils\\http_utils.py\", line 286, in request\n    response = self._make_request(method, url, **kwargs)\n  File \"E:\\bgtest\\utils\\http_utils.py\", line 129, in _make_request\n    response = self.session.request(\n        method=method,\n    ...<3 lines>...\n        **kwargs\n    )\n  File \"C:\\Python313\\Lib\\site-packages\\requests\\sessions.py\", line 589, in request\n    resp = self.send(prep, **send_kwargs)\n  File \"C:\\Python313\\Lib\\site-packages\\requests\\sessions.py\", line 703, in send\n    r = adapter.send(request, **kwargs)\n  File \"C:\\Python313\\Lib\\site-packages\\requests\\adapters.py\", line 700, in send\n    raise ConnectionError(e, request=request)\n"}, "steps": [{"name": "HTTP请求: POST http://localhost:8688/api/chatGatWay-internal", "status": "broken", "statusDetails": {"message": "requests.exceptions.ConnectionError: HTTPConnectionPool(host='localhost', port=8688): Max retries exceeded with url: /api/chatGatWay-internal (Caused by NewConnectionError('<urllib3.connection.HTTPConnection object at 0x000001A5B6A32E90>: Failed to establish a new connection: [WinError 10061] 由于目标计算机积极拒绝，无法连接。'))\n", "trace": "  File \"E:\\bgtest\\utils\\allure_utils.py\", line 282, in http_request_with_allure\n    response = http_utils.request(method, url, **kwargs)\n  File \"E:\\bgtest\\utils\\http_utils.py\", line 286, in request\n    response = self._make_request(method, url, **kwargs)\n  File \"E:\\bgtest\\utils\\http_utils.py\", line 129, in _make_request\n    response = self.session.request(\n        method=method,\n    ...<3 lines>...\n        **kwargs\n    )\n  File \"C:\\Python313\\Lib\\site-packages\\requests\\sessions.py\", line 589, in request\n    resp = self.send(prep, **send_kwargs)\n  File \"C:\\Python313\\Lib\\site-packages\\requests\\sessions.py\", line 703, in send\n    r = adapter.send(request, **kwargs)\n  File \"C:\\Python313\\Lib\\site-packages\\requests\\adapters.py\", line 700, in send\n    raise ConnectionError(e, request=request)\n"}, "attachments": [{"name": "Request Details", "source": "b863d49f-67f8-497f-832b-2d50aec3c955-attachment.json", "type": "application/json"}, {"name": "HTTP请求异常: POST http://localhost:8688/api/chatGatWay-internal", "source": "441cdec5-a40c-4c45-baec-dcc779999758-attachment.json", "type": "application/json"}], "start": 1754135083728, "stop": 1754135087825}], "attachments": [{"name": "错误信息", "source": "c50cbc23-31ae-48a3-bf2d-272654371819-attachment.txt", "type": "text/plain"}], "start": 1754135083728, "stop": 1754135087828}], "attachments": [{"name": "测试用例: 2", "source": "031a3c57-0b17-4ebf-9ab4-4a60f2343c26-attachment.json", "type": "application/json"}], "start": 1754135083725, "stop": 1754135087832}, {"name": "测试清理: Unknown.test_chat_gateway[case1]", "status": "passed", "start": 1754135088454, "stop": 1754135088461}], "attachments": [{"name": "测试异常", "source": "c355cd4b-9483-415b-8311-84b3e524613a-attachment.json", "type": "application/json"}, {"name": "异常堆栈", "source": "4ee0b25a-68f6-4015-865c-727bb44a7c08-attachment.txt", "type": "text/plain"}, {"name": "log", "source": "5d3080a4-0b8b-4b72-895d-0dcaf9626d77-attachment.txt", "type": "text/plain"}], "parameters": [{"name": "case", "value": "{'case_id': 2, 'description': '异常请求-缺少message参数', 'url': 'http://localhost:8688/api/chatGatWay-internal', 'method': 'POST', 'params': {'user_id': 'user002'}, 'expected_result': {'code': 400, 'msg': '参数缺失: message', 'data': {}}}"}], "start": 1754135083725, "stop": 1754135087837, "uuid": "98df6bb3-a02d-4c27-a2ef-afed878df8c2", "historyId": "f6f57a812db2780b726abc2497d09cfd", "testCaseId": "1978e2cdf027d526c50a4af93e30c525", "fullName": "testcase.test_chat_gateway#test_chat_gateway", "labels": [{"name": "feature", "value": "聊天网关"}, {"name": "story", "value": "API测试"}, {"name": "parentSuite", "value": "testcase"}, {"name": "suite", "value": "test_chat_gateway"}, {"name": "host", "value": "Ly0217"}, {"name": "thread", "value": "205488-MainThread"}, {"name": "framework", "value": "pytest"}, {"name": "language", "value": "cpython3"}, {"name": "package", "value": "testcase.test_chat_gateway"}], "titlePath": ["testcase", "test_chat_gateway.py"]}