[32mINFO    [0m project_logger:log.py:46 开始测试: TestDataDrivenExample.test_yaml_data_driven
[32mINFO    [0m project_logger:log.py:46 执行用例: 1 - 正常请求-简单问题
[32mINFO    [0m project_logger:log.py:46 请求地址: http://localhost:8688/api/chatGatWay-internal
[32mINFO    [0m project_logger:log.py:46 请求参数: {'message': '你好，今天天气怎么样？', 'user_id': 'user001'}
[32mINFO    [0m api_monitor_logger:log.py:57 HTTP请求开始: {"timestamp": 1754131828.5832765, "method": "POST", "url": "http://localhost:8688/api/chatGatWay-internal", "params": {}, "json_data": {"message": "你好，今天天气怎么样？", "user_id": "user001"}, "headers": {}}
[1m[31mERROR   [0m utils.http_utils:http_utils.py:147 请求失败: HTTPConnectionPool(host='localhost', port=8688): Max retries exceeded with url: /api/chatGatWay-internal (Caused by NewConnectionError('<urllib3.connection.HTTPConnection object at 0x0000023248D46D50>: Failed to establish a new connection: [WinError 10061] 由于目标计算机积极拒绝，无法连接。'))
[1m[31mERROR   [0m api_monitor_logger:log.py:61 HTTP请求失败: {"timestamp": 1754131832.636113, "method": "POST", "url": "http://localhost:8688/api/chatGatWay-internal", "status_code": null, "execution_time_ms": 4052.83, "response_size": 0, "status": "error", "error": "HTTPConnectionPool(host='localhost', port=8688): Max retries exceeded with url: /api/chatGatWay-internal (Caused by NewConnectionError('<urllib3.connection.HTTPConnection object at 0x0000023248D46D50>: Failed to establish a new connection: [WinError 10061] 由于目标计算机积极拒绝，无法连接。'))"}
[1m[31mERROR   [0m project_logger:log.py:49 测试用例执行失败: HTTPConnectionPool(host='localhost', port=8688): Max retries exceeded with url: /api/chatGatWay-internal (Caused by NewConnectionError('<urllib3.connection.HTTPConnection object at 0x0000023248D46D50>: Failed to establish a new connection: [WinError 10061] 由于目标计算机积极拒绝，无法连接。'))
[32mINFO    [0m project_logger:log.py:46 测试完成: TestDataDrivenExample.test_yaml_data_driven, 耗时: 4.06秒