[32mINFO    [0m project_logger:log.py:46 开始测试: TestDataDrivenExample.test_all_files_data_driven
[32mINFO    [0m project_logger:log.py:46 测试文件: test_http_data
[32mINFO    [0m project_logger:log.py:46 执行用例: 1 - 测试GET请求
[32mINFO    [0m project_logger:log.py:46 请求地址: https://jsonplaceholder.typicode.com/posts/1
[32mINFO    [0m project_logger:log.py:46 请求参数: {}
[32mINFO    [0m api_monitor_logger:log.py:57 HTTP请求开始: {"timestamp": 1754131817.836089, "method": "GET", "url": "https://jsonplaceholder.typicode.com/posts/1", "params": {}, "json_data": {}, "headers": {}}
[32mINFO    [0m api_monitor_logger:log.py:57 HTTP请求成功: {"timestamp": 1754131818.8039348, "method": "GET", "url": "https://jsonplaceholder.typicode.com/posts/1", "status_code": 200, "execution_time_ms": 967.84, "response_size": 292, "status": "success"}
[32mINFO    [0m project_logger:log.py:46 接口返回: {'userId': 1, 'id': 1, 'title': 'sunt aut facere repellat provident occaecati excepturi optio reprehenderit', 'body': 'quia et suscipit\nsuscipit recusandae consequuntur expedita et cum\nreprehenderit molestiae ut ut quas totam\nnostrum rerum est autem sunt rem eveniet architecto'}
[32mINFO    [0m project_logger:log.py:46 执行用例: 2 - 测试POST请求
[32mINFO    [0m project_logger:log.py:46 请求地址: https://jsonplaceholder.typicode.com/posts
[32mINFO    [0m project_logger:log.py:46 请求参数: {'title': 'test', 'body': 'test body', 'userId': 1}
[32mINFO    [0m api_monitor_logger:log.py:57 HTTP请求开始: {"timestamp": 1754131818.8057408, "method": "POST", "url": "https://jsonplaceholder.typicode.com/posts", "params": {}, "json_data": {"title": "test", "body": "test body", "userId": 1}, "headers": {}}
[32mINFO    [0m api_monitor_logger:log.py:57 HTTP请求成功: {"timestamp": 1754131820.211733, "method": "POST", "url": "https://jsonplaceholder.typicode.com/posts", "status_code": 201, "execution_time_ms": 1405.99, "response_size": 72, "status": "success"}
[32mINFO    [0m project_logger:log.py:46 接口返回: {'title': 'test', 'body': 'test body', 'userId': 1, 'id': 101}
[32mINFO    [0m project_logger:log.py:46 执行用例: 3 - 测试带参数GET
[32mINFO    [0m project_logger:log.py:46 请求地址: https://jsonplaceholder.typicode.com/posts/1
[32mINFO    [0m project_logger:log.py:46 请求参数: {}
[32mINFO    [0m api_monitor_logger:log.py:57 HTTP请求开始: {"timestamp": 1754131820.2133112, "method": "GET", "url": "https://jsonplaceholder.typicode.com/posts/1", "params": {}, "json_data": {}, "headers": {}}
[32mINFO    [0m api_monitor_logger:log.py:57 HTTP请求成功: {"timestamp": 1754131821.2723298, "method": "GET", "url": "https://jsonplaceholder.typicode.com/posts/1", "status_code": 200, "execution_time_ms": 1059.02, "response_size": 292, "status": "success"}
[32mINFO    [0m project_logger:log.py:46 接口返回: {'userId': 1, 'id': 1, 'title': 'sunt aut facere repellat provident occaecati excepturi optio reprehenderit', 'body': 'quia et suscipit\nsuscipit recusandae consequuntur expedita et cum\nreprehenderit molestiae ut ut quas totam\nnostrum rerum est autem sunt rem eveniet architecto'}
[32mINFO    [0m project_logger:log.py:46 测试文件: test_chat_gateway
[32mINFO    [0m project_logger:log.py:46 执行用例: 1 - 正常请求-简单问题
[32mINFO    [0m project_logger:log.py:46 请求地址: http://localhost:8688/api/chatGatWay-internal
[32mINFO    [0m project_logger:log.py:46 请求参数: {'message': '你好，今天天气怎么样？', 'user_id': 'user001'}
[32mINFO    [0m api_monitor_logger:log.py:57 HTTP请求开始: {"timestamp": 1754131821.2742794, "method": "POST", "url": "http://localhost:8688/api/chatGatWay-internal", "params": {}, "json_data": {"message": "你好，今天天气怎么样？", "user_id": "user001"}, "headers": {}}
[1m[31mERROR   [0m utils.http_utils:http_utils.py:147 请求失败: HTTPConnectionPool(host='localhost', port=8688): Max retries exceeded with url: /api/chatGatWay-internal (Caused by NewConnectionError('<urllib3.connection.HTTPConnection object at 0x000002324981A780>: Failed to establish a new connection: [WinError 10061] 由于目标计算机积极拒绝，无法连接。'))
[1m[31mERROR   [0m api_monitor_logger:log.py:61 HTTP请求失败: {"timestamp": 1754131825.3478825, "method": "POST", "url": "http://localhost:8688/api/chatGatWay-internal", "status_code": null, "execution_time_ms": 4073.6, "response_size": 0, "status": "error", "error": "HTTPConnectionPool(host='localhost', port=8688): Max retries exceeded with url: /api/chatGatWay-internal (Caused by NewConnectionError('<urllib3.connection.HTTPConnection object at 0x000002324981A780>: Failed to establish a new connection: [WinError 10061] 由于目标计算机积极拒绝，无法连接。'))"}
[1m[31mERROR   [0m project_logger:log.py:49 测试用例执行失败: HTTPConnectionPool(host='localhost', port=8688): Max retries exceeded with url: /api/chatGatWay-internal (Caused by NewConnectionError('<urllib3.connection.HTTPConnection object at 0x000002324981A780>: Failed to establish a new connection: [WinError 10061] 由于目标计算机积极拒绝，无法连接。'))
[32mINFO    [0m project_logger:log.py:46 慢速测试警告: TestDataDrivenExample.test_all_files_data_driven 耗时 7.51秒
[32mINFO    [0m project_logger:log.py:46 测试完成: TestDataDrivenExample.test_all_files_data_driven, 耗时: 7.52秒